Workbook
Name Slicer_AGE: #N/A
Name Slicer_Education_level: #N/A
Name Slicer_Region: #N/A
Name Slicer_Region1: #N/A
Name Slicer_State: #N/A

Sheet Patient Demographics
A1: Patient Id | B1: Patient Name | C1: Gender | D1: Date of Birth | E1: Updated_DOB | F1: Year_DOB | G1: AGE | H1: Age Group | I1: Income (LPA) | J1: Location (state) | K1: Region | L1: Updated_Region_Vlookup | M1: Updated_Region_Hlookup | N1: Updated_Region | O1: TRIM_NAME | P1: First_name | Q1: Name_01 | R1: Name_02 | S1: Report_Name | T1: Priority | U1: Further_Priority | V1: Further_Priority_IFS | W1: Region | X1: Count
A2: PID0001 | B2: Shreya Reddy | C2: Female | D2: 31/12/1973 | E2: =DATEVALUE(D2) -> 27029 | F2: =YEAR(E2) -> 1973 | G2: =$X$9-F2 -> 52 | H2: {=_xlfn.IFS( AND(G2>=21, G2<=30), "Young Adult", AND(G2>=31, G2<=45), "Adult", AND(G2>=46, G2<=60), "Middle-aged", AND(G2>=61, G2<=75), "Senior", AND(G2>=76, G2<=87), "Elderly", TRUE, "Out of Range" )} -> Middle-aged | I2: 20 | J2: Tamil Nadu | K2: South | L2: =VLOOKUP(J2,Facts!$A$2:$B$10,2,FALSE) -> South | M2: =HLOOKUP(J2,Facts!$D$13:$L$14,2,FALSE) -> South | N2: =_xlfn.XLOOKUP(L2,Facts!$B$2:$B$10,Facts!$A$2:$A$10,FALSE) -> Tamil Nadu | O2: =TRIM(B2) -> Shreya Reddy | P2: {=_xlfn.TEXTSPLIT(O2," ")} -> Shreya | Q2: Reddy | S2: =CONCATENATE(A2,"_",P2,".pdf") -> PID0001_Shreya.pdf | T2: =IF(AND(I2<5,'Billing Details'!F2>10000),"High Priority","Regular Followup") -> Regular Followup | U2: =IF(AND(T2="High Priority",'Patient Health Records'!W2="Yes",'Patient Health Records'!X2 = "Critical"),"Needs Attention",IF(AND('Patient Health Records'!X2 <> "Critical", 'Patient Health Records'!W2 = "Yes"),"Monitor Later",IF(AND('Patient Health Records'!X2 ="Critical", 'Patient Health Records'!W2 = "No"), "Ask for Readmission","No Action"))) -> Ask for Readmission | V2: {=_xlfn.IFS(AND(T2="High Priority",'Patient Health Records'!W2="Yes",'Patient Health Records'!X2 = "Critical"),"Needs Attention", AND('Patient Health Records'!X2 <> "Critical", 'Patient Health Records'!W2 = "Yes"),"Monitor Later", AND('Patient Health Records'!X2 ="Critical", 'Patient Health Records'!W2 = "No"), "Ask for Readmission", TRUE, "No Action")} -> Ask for Readmission | W2: {=_xlfn.UNIQUE(K:K)} -> Region | X2: Count_people
A3: PID0002 | B3: Isha Sharma | C3: Female | D3: 31/12/1953 | E3: =DATEVALUE(D3) -> 19724 | F3: =YEAR(E3) -> 1953 | G3: =$X$9-F3 -> 72 | H3: {=_xlfn.IFS( AND(G3>=21, G3<=30), "Young Adult", AND(G3>=31, G3<=45), "Adult", AND(G3>=46, G3<=60), "Middle-aged", AND(G3>=61, G3<=75), "Senior", AND(G3>=76, G3<=87), "Elderly", TRUE, "Out of Range" )} -> Senior | I3: 15 | J3: Maharashtra | K3: South | L3: West | M3: =HLOOKUP(J3,Facts!$D$13:$L$14,2,FALSE) -> West | N3: =_xlfn.XLOOKUP(L3,Facts!$B$2:$B$10,Facts!$A$2:$A$10,FALSE) -> Maharashtra | O3: =TRIM(B3) -> Isha Sharma | P3: {=_xlfn.TEXTSPLIT(O3," ")} -> Isha | Q3: Sharma | S3: =CONCATENATE(A3,"_",P3,".pdf") -> PID0002_Isha.pdf | T3: =IF(AND(I3<5,'Billing Details'!F3>10000),"High Priority","Regular Followup") -> Regular Followup | U3: =IF(AND(T3="High Priority",'Patient Health Records'!W3="Yes",'Patient Health Records'!X3 = "Critical"),"Needs Attention",IF(AND('Patient Health Records'!X3 <> "Critical", 'Patient Health Records'!W3 = "Yes"),"Monitor Later",IF(AND('Patient Health Records'!X3 ="Critical", 'Patient Health Records'!W3 = "No"), "Ask for Readmission","No Action"))) -> No Action | V3: {=_xlfn.IFS(AND(T3="High Priority",'Patient Health Records'!W3="Yes",'Patient Health Records'!X3 = "Critical"),"Needs Attention", AND('Patient Health Records'!X3 <> "Critical", 'Patient Health Records'!W3 = "Yes"),"Monitor Later", AND('Patient Health Records'!X3 ="Critical", 'Patient Health Records'!W3 = "No"), "Ask for Readmission", TRUE, "No Action")} -> No Action | W3: South | X3: =COUNTIFS(T:T,"High Priority",L:L,"South") -> 53
A4: PID0003 | B4: Isha Raj Reddy | C4: Female | D4: 31/12/1993 | E4: =DATEVALUE(D4) -> 34334 | F4: =YEAR(E4) -> 1993 | G4: =$X$9-F4 -> 32 | H4: {=_xlfn.IFS( AND(G4>=21, G4<=30), "Young Adult", AND(G4>=31, G4<=45), "Adult", AND(G4>=46, G4<=60), "Middle-aged", AND(G4>=61, G4<=75), "Senior", AND(G4>=76, G4<=87), "Elderly", TRUE, "Out of Range" )} -> Adult | I4: 20 | J4: Punjab | K4: North | L4: =VLOOKUP(J4,Facts!$A$2:$B$10,2,FALSE) -> North | M4: =HLOOKUP(J4,Facts!$D$13:$L$14,2,FALSE) -> North | N4: =_xlfn.XLOOKUP(L4,Facts!$B$2:$B$10,Facts!$A$2:$A$10,FALSE) -> Punjab | O4: =TRIM(B4) -> Isha Raj Reddy | P4: {=_xlfn.TEXTSPLIT(O4," ")} -> Isha | Q4: Raj | R4: Reddy | S4: =CONCATENATE(A4,"_",P4,".pdf") -> PID0003_Isha.pdf | T4: =IF(AND(I4<5,'Billing Details'!F4>10000),"High Priority","Regular Followup") -> Regular Followup | U4: =IF(AND(T4="High Priority",'Patient Health Records'!W4="Yes",'Patient Health Records'!X4 = "Critical"),"Needs Attention",IF(AND('Patient Health Records'!X4 <> "Critical", 'Patient Health Records'!W4 = "Yes"),"Monitor Later",IF(AND('Patient Health Records'!X4 ="Critical", 'Patient Health Records'!W4 = "No"), "Ask for Readmission","No Action"))) -> Ask for Readmission | V4: {=_xlfn.IFS(AND(T4="High Priority",'Patient Health Records'!W4="Yes",'Patient Health Records'!X4 = "Critical"),"Needs Attention", AND('Patient Health Records'!X4 <> "Critical", 'Patient Health Records'!W4 = "Yes"),"Monitor Later", AND('Patient Health Records'!X4 ="Critical", 'Patient Health Records'!W4 = "No"), "Ask for Readmission", TRUE, "No Action")} -> Ask for Readmission | W4: North | X4: =COUNTIFS(T:T,"High Priority",L:L,"North") -> 143
A5: PID0004 | B5: Aditya Patel | C5: Male | D5: 31/12/1993 | E5: =DATEVALUE(D5) -> 34334 | F5: =YEAR(E5) -> 1993 | G5: =$X$9-F5 -> 32 | H5: {=_xlfn.IFS( AND(G5>=21, G5<=30), "Young Adult", AND(G5>=31, G5<=45), "Adult", AND(G5>=46, G5<=60), "Middle-aged", AND(G5>=61, G5<=75), "Senior", AND(G5>=76, G5<=87), "Elderly", TRUE, "Out of Range" )} -> Adult | I5: 15 | J5: Karnataka | K5: South | L5: =VLOOKUP(J5,Facts!$A$2:$B$10,2,FALSE) -> South | M5: =HLOOKUP(J5,Facts!$D$13:$L$14,2,FALSE) -> South | N5: =_xlfn.XLOOKUP(L5,Facts!$B$2:$B$10,Facts!$A$2:$A$10,FALSE) -> Tamil Nadu | O5: =TRIM(B5) -> Aditya Patel | P5: {=_xlfn.TEXTSPLIT(O5," ")} -> Aditya | Q5: Patel | S5: =CONCATENATE(A5,"_",P5,".pdf") -> PID0004_Aditya.pdf | T5: =IF(AND(I5<5,'Billing Details'!F5>10000),"High Priority","Regular Followup") -> Regular Followup | U5: =IF(AND(T5="High Priority",'Patient Health Records'!W5="Yes",'Patient Health Records'!X5 = "Critical"),"Needs Attention",IF(AND('Patient Health Records'!X5 <> "Critical", 'Patient Health Records'!W5 = "Yes"),"Monitor Later",IF(AND('Patient Health Records'!X5 ="Critical", 'Patient Health Records'!W5 = "No"), "Ask for Readmission","No Action"))) -> Ask for Readmission | V5: {=_xlfn.IFS(AND(T5="High Priority",'Patient Health Records'!W5="Yes",'Patient Health Records'!X5 = "Critical"),"Needs Attention", AND('Patient Health Records'!X5 <> "Critical", 'Patient Health Records'!W5 = "Yes"),"Monitor Later", AND('Patient Health Records'!X5 ="Critical", 'Patient Health Records'!W5 = "No"), "Ask for Readmission", TRUE, "No Action")} -> Ask for Readmission | W5: East | X5: =COUNTIFS(T:T,"High Priority",L:L,"East") -> 26
A6: PID0005 | B6: Aarav Mehta | C6: Male | D6: 31/12/1988 | E6: =DATEVALUE(D6) -> 32508 | F6: =YEAR(E6) -> 1988 | G6: =$X$9-F6 -> 37 | H6: {=_xlfn.IFS( AND(G6>=21, G6<=30), "Young Adult", AND(G6>=31, G6<=45), "Adult", AND(G6>=46, G6<=60), "Middle-aged", AND(G6>=61, G6<=75), "Senior", AND(G6>=76, G6<=87), "Elderly", TRUE, "Out of Range" )} -> Adult | I6: 2 | J6: Uttar Pradesh | K6: North | L6: =VLOOKUP(J6,Facts!$A$2:$B$10,2,FALSE) -> North | M6: =HLOOKUP(J6,Facts!$D$13:$L$14,2,FALSE) -> North | N6: =_xlfn.XLOOKUP(L6,Facts!$B$2:$B$10,Facts!$A$2:$A$10,FALSE) -> Punjab | O6: =TRIM(B6) -> Aarav Mehta | P6: {=_xlfn.TEXTSPLIT(O6," ")} -> Aarav | Q6: Mehta | S6: =CONCATENATE(A6,"_",P6,".pdf") -> PID0005_Aarav.pdf | T6: =IF(AND(I6<5,'Billing Details'!F6>10000),"High Priority","Regular Followup") -> High Priority | U6: =IF(AND(T6="High Priority",'Patient Health Records'!W6="Yes",'Patient Health Records'!X6 = "Critical"),"Needs Attention",IF(AND('Patient Health Records'!X6 <> "Critical", 'Patient Health Records'!W6 = "Yes"),"Monitor Later",IF(AND('Patient Health Records'!X6 ="Critical", 'Patient Health Records'!W6 = "No"), "Ask for Readmission","No Action"))) -> Needs Attention | V6: {=_xlfn.IFS(AND(T6="High Priority",'Patient Health Records'!W6="Yes",'Patient Health Records'!X6 = "Critical"),"Needs Attention", AND('Patient Health Records'!X6 <> "Critical", 'Patient Health Records'!W6 = "Yes"),"Monitor Later", AND('Patient Health Records'!X6 ="Critical", 'Patient Health Records'!W6 = "No"), "Ask for Readmission", TRUE, "No Action")} -> Needs Attention | W6: West | X6: =COUNTIFS(T:T,"High Priority",L:L,"West") -> 4
A7: PID0006 | B7: Aarav Sharma | C7: Male | D7: 31/12/1938 | E7: =DATEVALUE(D7) -> 14245 | F7: =YEAR(E7) -> 1938 | G7: =$X$9-F7 -> 87 | H7: {=_xlfn.IFS( AND(G7>=21, G7<=30), "Young Adult", AND(G7>=31, G7<=45), "Adult", AND(G7>=46, G7<=60), "Middle-aged", AND(G7>=61, G7<=75), "Senior", AND(G7>=76, G7<=87), "Elderly", TRUE, "Out of Range" )} -> Elderly | I7: 20 | J7: Karnataka | K7: South | L7: =VLOOKUP(J7,Facts!$A$2:$B$10,2,FALSE) -> South | M7: =HLOOKUP(J7,Facts!$D$13:$L$14,2,FALSE) -> South | N7: =_xlfn.XLOOKUP(L7,Facts!$B$2:$B$10,Facts!$A$2:$A$10,FALSE) -> Tamil Nadu | O7: =TRIM(B7) -> Aarav Sharma | P7: {=_xlfn.TEXTSPLIT(O7," ")} -> Aarav | Q7: Sharma | S7: =CONCATENATE(A7,"_",P7,".pdf") -> PID0006_Aarav.pdf | T7: =IF(AND(I7<5,'Billing Details'!F7>10000),"High Priority","Regular Followup") -> Regular Followup | U7: =IF(AND(T7="High Priority",'Patient Health Records'!W7="Yes",'Patient Health Records'!X7 = "Critical"),"Needs Attention",IF(AND('Patient Health Records'!X7 <> "Critical", 'Patient Health Records'!W7 = "Yes"),"Monitor Later",IF(AND('Patient Health Records'!X7 ="Critical", 'Patient Health Records'!W7 = "No"), "Ask for Readmission","No Action"))) -> No Action | V7: {=_xlfn.IFS(AND(T7="High Priority",'Patient Health Records'!W7="Yes",'Patient Health Records'!X7 = "Critical"),"Needs Attention", AND('Patient Health Records'!X7 <> "Critical", 'Patient Health Records'!W7 = "Yes"),"Monitor Later", AND('Patient Health Records'!X7 ="Critical", 'Patient Health Records'!W7 = "No"), "Ask for Readmission", TRUE, "No Action")} -> No Action | W7: 0
A8: PID0007 | B8: Sai Raj Patel | C8: Male | D8: 31/12/1988 | E8: =DATEVALUE(D8) -> 32508 | F8: =YEAR(E8) -> 1988 | G8: =$X$9-F8 -> 37 | H8: {=_xlfn.IFS( AND(G8>=21, G8<=30), "Young Adult", AND(G8>=31, G8<=45), "Adult", AND(G8>=46, G8<=60), "Middle-aged", AND(G8>=61, G8<=75), "Senior", AND(G8>=76, G8<=87), "Elderly", TRUE, "Out of Range" )} -> Adult | I8: 40 | J8: Maharashtra | K8: North | L8: =VLOOKUP(J8,Facts!$A$2:$B$10,2,FALSE) -> West | M8: =HLOOKUP(J8,Facts!$D$13:$L$14,2,FALSE) -> West | N8: =_xlfn.XLOOKUP(L8,Facts!$B$2:$B$10,Facts!$A$2:$A$10,FALSE) -> Maharashtra | O8: =TRIM(B8) -> Sai Raj Patel | P8: {=_xlfn.TEXTSPLIT(O8," ")} -> Sai | Q8: Raj | R8: Patel | S8: =CONCATENATE(A8,"_",P8,".pdf") -> PID0007_Sai.pdf | T8: =IF(AND(I8<5,'Billing Details'!F8>10000),"High Priority","Regular Followup") -> Regular Followup | U8: =IF(AND(T8="High Priority",'Patient Health Records'!W8="Yes",'Patient Health Records'!X8 = "Critical"),"Needs Attention",IF(AND('Patient Health Records'!X8 <> "Critical", 'Patient Health Records'!W8 = "Yes"),"Monitor Later",IF(AND('Patient Health Records'!X8 ="Critical", 'Patient Health Records'!W8 = "No"), "Ask for Readmission","No Action"))) -> No Action | V8: {=_xlfn.IFS(AND(T8="High Priority",'Patient Health Records'!W8="Yes",'Patient Health Records'!X8 = "Critical"),"Needs Attention", AND('Patient Health Records'!X8 <> "Critical", 'Patient Health Records'!W8 = "Yes"),"Monitor Later", AND('Patient Health Records'!X8 ="Critical", 'Patient Health Records'!W8 = "No"), "Ask for Readmission", TRUE, "No Action")} -> No Action
A9: PID0008 | B9: Shreya Reddy | C9: Female | D9: 31/12/1994 | E9: =DATEVALUE(D9) -> 34699 | F9: =YEAR(E9) -> 1994 | G9: =$X$9-F9 -> 31 | H9: {=_xlfn.IFS( AND(G9>=21, G9<=30), "Young Adult", AND(G9>=31, G9<=45), "Adult", AND(G9>=46, G9<=60), "Middle-aged", AND(G9>=61, G9<=75), "Senior", AND(G9>=76, G9<=87), "Elderly", TRUE, "Out of Range" )} -> Adult | I9: 30 | J9: Kerala | K9: East | L9: =VLOOKUP(J9,Facts!$A$2:$B$10,2,FALSE) -> South | M9: =HLOOKUP(J9,Facts!$D$13:$L$14,2,FALSE) -> South | N9: =_xlfn.XLOOKUP(L9,Facts!$B$2:$B$10,Facts!$A$2:$A$10,FALSE) -> Tamil Nadu | O9: =TRIM(B9) -> Shreya Reddy | P9: {=_xlfn.TEXTSPLIT(O9," ")} -> Shreya | Q9: Reddy | S9: =CONCATENATE(A9,"_",P9,".pdf") -> PID0008_Shreya.pdf | T9: =IF(AND(I9<5,'Billing Details'!F9>10000),"High Priority","Regular Followup") -> Regular Followup | U9: =IF(AND(T9="High Priority",'Patient Health Records'!W9="Yes",'Patient Health Records'!X9 = "Critical"),"Needs Attention",IF(AND('Patient Health Records'!X9 <> "Critical", 'Patient Health Records'!W9 = "Yes"),"Monitor Later",IF(AND('Patient Health Records'!X9 ="Critical", 'Patient Health Records'!W9 = "No"), "Ask for Readmission","No Action"))) -> Monitor Later | V9: {=_xlfn.IFS(AND(T9="High Priority",'Patient Health Records'!W9="Yes",'Patient Health Records'!X9 = "Critical"),"Needs Attention", AND('Patient Health Records'!X9 <> "Critical", 'Patient Health Records'!W9 = "Yes"),"Monitor Later", AND('Patient Health Records'!X9 ="Critical", 'Patient Health Records'!W9 = "No"), "Ask for Readmission", TRUE, "No Action")} -> Monitor Later | W9: Current_year | X9: 2025
A10: PID0009 | B10: Diya Mehta | C10: Female | D10: 31/12/1978 | E10: =DATEVALUE(D10) -> 28855 | F10: =YEAR(E10) -> 1978 | G10: =$X$9-F10 -> 47 | H10: {=_xlfn.IFS( AND(G10>=21, G10<=30), "Young Adult", AND(G10>=31, G10<=45), "Adult", AND(G10>=46, G10<=60), "Middle-aged", AND(G10>=61, G10<=75), "Senior", AND(G10>=76, G10<=87), "Elderly", TRUE, "Out of Range" )} -> Middle-aged | I10: 20 | J10: Karnataka | K10: South | L10: =VLOOKUP(J10,Facts!$A$2:$B$10,2,FALSE) -> South | M10: =HLOOKUP(J10,Facts!$D$13:$L$14,2,FALSE) -> South | N10: =_xlfn.XLOOKUP(L10,Facts!$B$2:$B$10,Facts!$A$2:$A$10,FALSE) -> Tamil Nadu | O10: =TRIM(B10) -> Diya Mehta | P10: {=_xlfn.TEXTSPLIT(O10," ")} -> Diya | Q10: Mehta | S10: =CONCATENATE(A10,"_",P10,".pdf") -> PID0009_Diya.pdf | T10: =IF(AND(I10<5,'Billing Details'!F10>10000),"High Priority","Regular Followup") -> Regular Followup | U10: =IF(AND(T10="High Priority",'Patient Health Records'!W10="Yes",'Patient Health Records'!X10 = "Critical"),"Needs Attention",IF(AND('Patient Health Records'!X10 <> "Critical", 'Patient Health Records'!W10 = "Yes"),"Monitor Later",IF(AND('Patient Health Records'!X10 ="Critical", 'Patient Health Records'!W10 = "No"), "Ask for Readmission","No Action"))) -> No Action | V10: {=_xlfn.IFS(AND(T10="High Priority",'Patient Health Records'!W10="Yes",'Patient Health Records'!X10 = "Critical"),"Needs Attention", AND('Patient Health Records'!X10 <> "Critical", 'Patient Health Records'!W10 = "Yes"),"Monitor Later", AND('Patient Health Records'!X10 ="Critical", 'Patient Health Records'!W10 = "No"), "Ask for Readmission", TRUE, "No Action")} -> No Action
A11: PID0010 | B11: Vivaan Patel | C11: Male | D11: 31-12-1994 | E11: =DATEVALUE(D11) -> 34699 | F11: =YEAR(E11) -> 1994 | G11: =$X$9-F11 -> 31 | H11: {=_xlfn.IFS( AND(G11>=21, G11<=30), "Young Adult", AND(G11>=31, G11<=45), "Adult", AND(G11>=46, G11<=60), "Middle-aged", AND(G11>=61, G11<=75), "Senior", AND(G11>=76, G11<=87), "Elderly", TRUE, "Out of Range" )} -> Adult | I11: 2 | J11: West Bengal | K11: East | L11: =VLOOKUP(J11,Facts!$A$2:$B$10,2,FALSE) -> East | M11: =HLOOKUP(J11,Facts!$D$13:$L$14,2,FALSE) -> East | N11: =_xlfn.XLOOKUP(L11,Facts!$B$2:$B$10,Facts!$A$2:$A$10,FALSE) -> West Bengal | O11: =TRIM(B11) -> Vivaan Patel | P11: {=_xlfn.TEXTSPLIT(O11," ")} -> Vivaan | Q11: Patel | S11: =CONCATENATE(A11,"_",P11,".pdf") -> PID0010_Vivaan.pdf | T11: =IF(AND(I11<5,'Billing Details'!F11>10000),"High Priority","Regular Followup") -> High Priority | U11: =IF(AND(T11="High Priority",'Patient Health Records'!W11="Yes",'Patient Health Records'!X11 = "Critical"),"Needs Attention",IF(AND('Patient Health Records'!X11 <> "Critical", 'Patient Health Records'!W11 = "Yes"),"Monitor Later",IF(AND('Patient Health Records'!X11 ="Critical", 'Patient Health Records'!W11 = "No"), "Ask for Readmission","No Action"))) -> Ask for Readmission | V11: {=_xlfn.IFS(AND(T11="High Priority",'Patient Health Records'!W11="Yes",'Patient Health Records'!X11 = "Critical"),"Needs Attention", AND('Patient Health Records'!X11 <> "Critical", 'Patient Health Records'!W11 = "Yes"),"Monitor Later", AND('Patient Health Records'!X11 ="Critical", 'Patient Health Records'!W11 = "No"), "Ask for Readmission", TRUE, "No Action")} -> Ask for Readmission | W11: List of Age Group | X11: Count
A12: PID0011 | B12: Aditya Gupta | C12: Male | D12: 01/01/1964 | E12: =DATEVALUE(D12) -> 23377 | F12: =YEAR(E12) -> 1964 | G12: =$X$9-F12 -> 61 | H12: {=_xlfn.IFS( AND(G12>=21, G12<=30), "Young Adult", AND(G12>=31, G12<=45), "Adult", AND(G12>=46, G12<=60), "Middle-aged", AND(G12>=61, G12<=75), "Senior", AND(G12>=76, G12<=87), "Elderly", TRUE, "Out of Range" )} -> Senior | I12: 3 | J12: Karnataka | K12: North | L12: =VLOOKUP(J12,Facts!$A$2:$B$10,2,FALSE) -> South | M12: =HLOOKUP(J12,Facts!$D$13:$L$14,2,FALSE) -> South | N12: =_xlfn.XLOOKUP(L12,Facts!$B$2:$B$10,Facts!$A$2:$A$10,FALSE) -> Tamil Nadu | O12: =TRIM(B12) -> Aditya Gupta | P12: {=_xlfn.TEXTSPLIT(O12," ")} -> Aditya | Q12: Gupta | S12: =CONCATENATE(A12,"_",P12,".pdf") -> PID0011_Aditya.pdf | T12: =IF(AND(I12<5,'Billing Details'!F12>10000),"High Priority","Regular Followup") -> High Priority | U12: =IF(AND(T12="High Priority",'Patient Health Records'!W12="Yes",'Patient Health Records'!X12 = "Critical"),"Needs Attention",IF(AND('Patient Health Records'!X12 <> "Critical", 'Patient Health Records'!W12 = "Yes"),"Monitor Later",IF(AND('Patient Health Records'!X12 ="Critical", 'Patient Health Records'!W12 = "No"), "Ask for Readmission","No Action"))) -> No Action | V12: {=_xlfn.IFS(AND(T12="High Priority",'Patient Health Records'!W12="Yes",'Patient Health Records'!X12 = "Critical"),"Needs Attention", AND('Patient Health Records'!X12 <> "Critical", 'Patient Health Records'!W12 = "Yes"),"Monitor Later", AND('Patient Health Records'!X12 ="Critical", 'Patient Health Records'!W12 = "No"), "Ask for Readmission", TRUE, "No Action")} -> No Action | W12: {=_xlfn.UNIQUE(H:H)} -> Age Group | X12: =COUNTIF(H:H,W12) -> 1
A13: PID0012 | B13: Aditya Sharma | C13: Male | D13: 01/01/1964 | E13: =DATEVALUE(D13) -> 23377 | F13: =YEAR(E13) -> 1964 | G13: =$X$9-F13 -> 61 | H13: {=_xlfn.IFS( AND(G13>=21, G13<=30), "Young Adult", AND(G13>=31, G13<=45), "Adult", AND(G13>=46, G13<=60), "Middle-aged", AND(G13>=61, G13<=75), "Senior", AND(G13>=76, G13<=87), "Elderly", TRUE, "Out of Range" )} -> Senior | I13: 15 | J13: Tamil Nadu | K13: South | L13: =VLOOKUP(J13,Facts!$A$2:$B$10,2,FALSE) -> South | M13: =HLOOKUP(J13,Facts!$D$13:$L$14,2,FALSE) -> South | N13: =_xlfn.XLOOKUP(L13,Facts!$B$2:$B$10,Facts!$A$2:$A$10,FALSE) -> Tamil Nadu | O13: =TRIM(B13) -> Aditya Sharma | P13: {=_xlfn.TEXTSPLIT(O13," ")} -> Aditya | Q13: Sharma | S13: =CONCATENATE(A13,"_",P13,".pdf") -> PID0012_Aditya.pdf | T13: =IF(AND(I13<5,'Billing Details'!F13>10000),"High Priority","Regular Followup") -> Regular Followup | U13: =IF(AND(T13="High Priority",'Patient Health Records'!W13="Yes",'Patient Health Records'!X13 = "Critical"),"Needs Attention",IF(AND('Patient Health Records'!X13 <> "Critical", 'Patient Health Records'!W13 = "Yes"),"Monitor Later",IF(AND('Patient Health Records'!X13 ="Critical", 'Patient Health Records'!W13 = "No"), "Ask for Readmission","No Action"))) -> Monitor Later | V13: {=_xlfn.IFS(AND(T13="High Priority",'Patient Health Records'!W13="Yes",'Patient Health Records'!X13 = "Critical"),"Needs Attention", AND('Patient Health Records'!X13 <> "Critical", 'Patient Health Records'!W13 = "Yes"),"Monitor Later", AND('Patient Health Records'!X13 ="Critical", 'Patient Health Records'!W13 = "No"), "Ask for Readmission", TRUE, "No Action")} -> Monitor Later | W13: Middle-aged | X13: =COUNTIF(H:H,W13) -> 351
A14: PID0013 | B14: Diya Kumar Sharma | C14: Female | D14: 31/12/1973 | E14: =DATEVALUE(D14) -> 27029 | F14: =YEAR(E14) -> 1973 | G14: =$X$9-F14 -> 52 | H14: {=_xlfn.IFS( AND(G14>=21, G14<=30), "Young Adult", AND(G14>=31, G14<=45), "Adult", AND(G14>=46, G14<=60), "Middle-aged", AND(G14>=61, G14<=75), "Senior", AND(G14>=76, G14<=87), "Elderly", TRUE, "Out of Range" )} -> Middle-aged | I14: 7 | J14: Kerala | K14: North | L14: =VLOOKUP(J14,Facts!$A$2:$B$10,2,FALSE) -> South | M14: =HLOOKUP(J14,Facts!$D$13:$L$14,2,FALSE) -> South | N14: =_xlfn.XLOOKUP(L14,Facts!$B$2:$B$10,Facts!$A$2:$A$10,FALSE) -> Tamil Nadu | O14: =TRIM(B14) -> Diya Kumar Sharma | P14: {=_xlfn.TEXTSPLIT(O14," ")} -> Diya | Q14: Kumar | R14: Sharma | S14: =CONCATENATE(A14,"_",P14,".pdf") -> PID0013_Diya.pdf | T14: =IF(AND(I14<5,'Billing Details'!F14>10000),"High Priority","Regular Followup") -> Regular Followup | U14: =IF(AND(T14="High Priority",'Patient Health Records'!W14="Yes",'Patient Health Records'!X14 = "Critical"),"Needs Attention",IF(AND('Patient Health Records'!X14 <> "Critical", 'Patient Health Records'!W14 = "Yes"),"Monitor Later",IF(AND('Patient Health Records'!X14 ="Critical", 'Patient Health Records'!W14 = "No"), "Ask for Readmission","No Action"))) -> Monitor Later | V14: {=_xlfn.IFS(AND(T14="High Priority",'Patient Health Records'!W14="Yes",'Patient Health Records'!X14 = "Critical"),"Needs Attention", AND('Patient Health Records'!X14 <> "Critical", 'Patient Health Records'!W14 = "Yes"),"Monitor Later", AND('Patient Health Records'!X14 ="Critical", 'Patient Health Records'!W14 = "No"), "Ask for Readmission", TRUE, "No Action")} -> Monitor Later | W14: Senior | X14: =COUNTIF(H:H,W14) -> 180
A15: PID0014 | B15: Aanya Raj Sharma | C15: Female | D15: 31/12/1981 | E15: =DATEVALUE(D15) -> 29951 | F15: =YEAR(E15) -> 1981 | G15: =$X$9-F15 -> 44 | H15: {=_xlfn.IFS( AND(G15>=21, G15<=30), "Young Adult", AND(G15>=31, G15<=45), "Adult", AND(G15>=46, G15<=60), "Middle-aged", AND(G15>=61, G15<=75), "Senior", AND(G15>=76, G15<=87), "Elderly", TRUE, "Out of Range" )} -> Adult | I15: 15 | J15: Kerala | K15: South | L15: =VLOOKUP(J15,Facts!$A$2:$B$10,2,FALSE) -> South | M15: =HLOOKUP(J15,Facts!$D$13:$L$14,2,FALSE) -> South | N15: =_xlfn.XLOOKUP(L15,Facts!$B$2:$B$10,Facts!$A$2:$A$10,FALSE) -> Tamil Nadu | O15: =TRIM(B15) -> Aanya Raj Sharma | P15: {=_xlfn.TEXTSPLIT(O15," ")} -> Aanya | Q15: Raj | R15: Sharma | S15: =CONCATENATE(A15,"_",P15,".pdf") -> PID0014_Aanya.pdf | T15: =IF(AND(I15<5,'Billing Details'!F15>10000),"High Priority","Regular Followup") -> Regular Followup | U15: =IF(AND(T15="High Priority",'Patient Health Records'!W15="Yes",'Patient Health Records'!X15 = "Critical"),"Needs Attention",IF(AND('Patient Health Records'!X15 <> "Critical", 'Patient Health Records'!W15 = "Yes"),"Monitor Later",IF(AND('Patient Health Records'!X15 ="Critical", 'Patient Health Records'!W15 = "No"), "Ask for Readmission","No Action"))) -> No Action | V15: {=_xlfn.IFS(AND(T15="High Priority",'Patient Health Records'!W15="Yes",'Patient Health Records'!X15 = "Critical"),"Needs Attention", AND('Patient Health Records'!X15 <> "Critical", 'Patient Health Records'!W15 = "Yes"),"Monitor Later", AND('Patient Health Records'!X15 ="Critical", 'Patient Health Records'!W15 = "No"), "Ask for Readmission", TRUE, "No Action")} -> No Action | W15: Adult | X15: =COUNTIF(H:H,W15) -> 426
A16: PID0015 | B16: Diya Priya Gupta | C16: Female | D16: 01/01/1964 | E16: =DATEVALUE(D16) -> 23377 | F16: =YEAR(E16) -> 1964 | G16: =$X$9-F16 -> 61 | H16: {=_xlfn.IFS( AND(G16>=21, G16<=30), "Young Adult", AND(G16>=31, G16<=45), "Adult", AND(G16>=46, G16<=60), "Middle-aged", AND(G16>=61, G16<=75), "Senior", AND(G16>=76, G16<=87), "Elderly", TRUE, "Out of Range" )} -> Senior | I16: 2 | J16: Uttar Pradesh | K16: North | L16: =VLOOKUP(J16,Facts!$A$2:$B$10,2,FALSE) -> North | M16: =HLOOKUP(J16,Facts!$D$13:$L$14,2,FALSE) -> North | N16: =_xlfn.XLOOKUP(L16,Facts!$B$2:$B$10,Facts!$A$2:$A$10,FALSE) -> Punjab | O16: =TRIM(B16) -> Diya Priya Gupta | P16: {=_xlfn.TEXTSPLIT(O16," ")} -> Diya | Q16: Priya | R16: Gupta | S16: =CONCATENATE(A16,"_",P16,".pdf") -> PID0015_Diya.pdf | T16: =IF(AND(I16<5,'Billing Details'!F16>10000),"High Priority","Regular Followup") -> High Priority | U16: =IF(AND(T16="High Priority",'Patient Health Records'!W16="Yes",'Patient Health Records'!X16 = "Critical"),"Needs Attention",IF(AND('Patient Health Records'!X16 <> "Critical", 'Patient Health Records'!W16 = "Yes"),"Monitor Later",IF(AND('Patient Health Records'!X16 ="Critical", 'Patient Health Records'!W16 = "No"), "Ask for Readmission","No Action"))) -> Ask for Readmission | V16: {=_xlfn.IFS(AND(T16="High Priority",'Patient Health Records'!W16="Yes",'Patient Health Records'!X16 = "Critical"),"Needs Attention", AND('Patient Health Records'!X16 <> "Critical", 'Patient Health Records'!W16 = "Yes"),"Monitor Later", AND('Patient Health Records'!X16 ="Critical", 'Patient Health Records'!W16 = "No"), "Ask for Readmission", TRUE, "No Action")} -> Ask for Readmission | W16: Elderly | X16: =COUNTIF(H:H,W16) -> 11
A17: PID0016 | B17: Isha Kumar Mehta | C17: Female | D17: 31/12/1994 | E17: =DATEVALUE(D17) -> 34699 | F17: =YEAR(E17) -> 1994 | G17: =$X$9-F17 -> 31 | H17: {=_xlfn.IFS( AND(G17>=21, G17<=30), "Young Adult", AND(G17>=31, G17<=45), "Adult", AND(G17>=46, G17<=60), "Middle-aged", AND(G17>=61, G17<=75), "Senior", AND(G17>=76, G17<=87), "Elderly", TRUE, "Out of Range" )} -> Adult | I17: 15 | J17: Gujarat | K17: South | L17: =VLOOKUP(J17,Facts!$A$2:$B$10,2,FALSE) -> West | M17: =HLOOKUP(J17,Facts!$D$13:$L$14,2,FALSE) -> West | N17: =_xlfn.XLOOKUP(L17,Facts!$B$2:$B$10,Facts!$A$2:$A$10,FALSE) -> Maharashtra | O17: =TRIM(B17) -> Isha Kumar Mehta | P17: {=_xlfn.TEXTSPLIT(O17," ")} -> Isha | Q17: Kumar | R17: Mehta | S17: =CONCATENATE(A17,"_",P17,".pdf") -> PID0016_Isha.pdf | T17: =IF(AND(I17<5,'Billing Details'!F17>10000),"High Priority","Regular Followup") -> Regular Followup | U17: =IF(AND(T17="High Priority",'Patient Health Records'!W17="Yes",'Patient Health Records'!X17 = "Critical"),"Needs Attention",IF(AND('Patient Health Records'!X17 <> "Critical", 'Patient Health Records'!W17 = "Yes"),"Monitor Later",IF(AND('Patient Health Records'!X17 ="Critical", 'Patient Health Records'!W17 = "No"), "Ask for Readmission","No Action"))) -> Monitor Later | V17: {=_xlfn.IFS(AND(T17="High Priority",'Patient Health Records'!W17="Yes",'Patient Health Records'!X17 = "Critical"),"Needs Attention", AND('Patient Health Records'!X17 <> "Critical", 'Patient Health Records'!W17 = "Yes"),"Monitor Later", AND('Patient Health Records'!X17 ="Critical", 'Patient Health Records'!W17 = "No"), "Ask for Readmission", TRUE, "No Action")} -> Monitor Later | W17: Young Adult | X17: =COUNTIF(H:H,W17) -> 32
A18: PID0017 | B18: Aditya Patel | C18: Male | D18: 01/01/1984 | E18: =DATEVALUE(D18) -> 30682 | F18: =YEAR(E18) -> 1984 | G18: =$X$9-F18 -> 41 | H18: {=_xlfn.IFS( AND(G18>=21, G18<=30), "Young Adult", AND(G18>=31, G18<=45), "Adult", AND(G18>=46, G18<=60), "Middle-aged", AND(G18>=61, G18<=75), "Senior", AND(G18>=76, G18<=87), "Elderly", TRUE, "Out of Range" )} -> Adult | I18: 7 | J18: Kerala | K18: South | L18: =VLOOKUP(J18,Facts!$A$2:$B$10,2,FALSE) -> South | M18: =HLOOKUP(J18,Facts!$D$13:$L$14,2,FALSE) -> South | N18: =_xlfn.XLOOKUP(L18,Facts!$B$2:$B$10,Facts!$A$2:$A$10,FALSE) -> Tamil Nadu | O18: =TRIM(B18) -> Aditya Patel | P18: {=_xlfn.TEXTSPLIT(O18," ")} -> Aditya | Q18: Patel | S18: =CONCATENATE(A18,"_",P18,".pdf") -> PID0017_Aditya.pdf | T18: =IF(AND(I18<5,'Billing Details'!F18>10000),"High Priority","Regular Followup") -> Regular Followup | U18: =IF(AND(T18="High Priority",'Patient Health Records'!W18="Yes",'Patient Health Records'!X18 = "Critical"),"Needs Attention",IF(AND('Patient Health Records'!X18 <> "Critical", 'Patient Health Records'!W18 = "Yes"),"Monitor Later",IF(AND('Patient Health Records'!X18 ="Critical", 'Patient Health Records'!W18 = "No"), "Ask for Readmission","No Action"))) -> No Action | V18: {=_xlfn.IFS(AND(T18="High Priority",'Patient Health Records'!W18="Yes",'Patient Health Records'!X18 = "Critical"),"Needs Attention", AND('Patient Health Records'!X18 <> "Critical", 'Patient Health Records'!W18 = "Yes"),"Monitor Later", AND('Patient Health Records'!X18 ="Critical", 'Patient Health Records'!W18 = "No"), "Ask for Readmission", TRUE, "No Action")} -> No Action | W18: 0
A19: PID0018 | B19: Riya Kumar Gupta | C19: Female | D19: 31/12/1968 | E19: =DATEVALUE(D19) -> 25203 | F19: =YEAR(E19) -> 1968 | G19: =$X$9-F19 -> 57 | H19: {=_xlfn.IFS( AND(G19>=21, G19<=30), "Young Adult", AND(G19>=31, G19<=45), "Adult", AND(G19>=46, G19<=60), "Middle-aged", AND(G19>=61, G19<=75), "Senior", AND(G19>=76, G19<=87), "Elderly", TRUE, "Out of Range" )} -> Middle-aged | I19: 3 | J19: Karnataka | K19: East | L19: =VLOOKUP(J19,Facts!$A$2:$B$10,2,FALSE) -> South | M19: =HLOOKUP(J19,Facts!$D$13:$L$14,2,FALSE) -> South | N19: =_xlfn.XLOOKUP(L19,Facts!$B$2:$B$10,Facts!$A$2:$A$10,FALSE) -> Tamil Nadu | O19: =TRIM(B19) -> Riya Kumar Gupta | P19: {=_xlfn.TEXTSPLIT(O19," ")} -> Riya | Q19: Kumar | R19: Gupta | S19: =CONCATENATE(A19,"_",P19,".pdf") -> PID0018_Riya.pdf | T19: =IF(AND(I19<5,'Billing Details'!F19>10000),"High Priority","Regular Followup") -> High Priority | U19: =IF(AND(T19="High Priority",'Patient Health Records'!W19="Yes",'Patient Health Records'!X19 = "Critical"),"Needs Attention",IF(AND('Patient Health Records'!X19 <> "Critical", 'Patient Health Records'!W19 = "Yes"),"Monitor Later",IF(AND('Patient Health Records'!X19 ="Critical", 'Patient Health Records'!W19 = "No"), "Ask for Readmission","No Action"))) -> Ask for Readmission | V19: {=_xlfn.IFS(AND(T19="High Priority",'Patient Health Records'!W19="Yes",'Patient Health Records'!X19 = "Critical"),"Needs Attention", AND('Patient Health Records'!X19 <> "Critical", 'Patient Health Records'!W19 = "Yes"),"Monitor Later", AND('Patient Health Records'!X19 ="Critical", 'Patient Health Records'!W19 = "No"), "Ask for Readmission", TRUE, "No Action")} -> Ask for Readmission | W19: =MAX(X12:X17) -> 426 | X19: Adult
A20: PID0019 | B20: Shreya Sharma | C20: Female | D20: 31/12/1981 | E20: =DATEVALUE(D20) -> 29951 | F20: =YEAR(E20) -> 1981 | G20: =$X$9-F20 -> 44 | H20: {=_xlfn.IFS( AND(G20>=21, G20<=30), "Young Adult", AND(G20>=31, G20<=45), "Adult", AND(G20>=46, G20<=60), "Middle-aged", AND(G20>=61, G20<=75), "Senior", AND(G20>=76, G20<=87), "Elderly", TRUE, "Out of Range" )} -> Adult | I20: 4 | J20: Karnataka | K20: South | L20: =VLOOKUP(J20,Facts!$A$2:$B$10,2,FALSE) -> South | M20: =HLOOKUP(J20,Facts!$D$13:$L$14,2,FALSE) -> South | N20: =_xlfn.XLOOKUP(L20,Facts!$B$2:$B$10,Facts!$A$2:$A$10,FALSE) -> Tamil Nadu | O20: =TRIM(B20) -> Shreya Sharma | P20: {=_xlfn.TEXTSPLIT(O20," ")} -> Shreya | Q20: Sharma | S20: =CONCATENATE(A20,"_",P20,".pdf") -> PID0019_Shreya.pdf | T20: =IF(AND(I20<5,'Billing Details'!F20>10000),"High Priority","Regular Followup") -> High Priority | U20: =IF(AND(T20="High Priority",'Patient Health Records'!W20="Yes",'Patient Health Records'!X20 = "Critical"),"Needs Attention",IF(AND('Patient Health Records'!X20 <> "Critical", 'Patient Health Records'!W20 = "Yes"),"Monitor Later",IF(AND('Patient Health Records'!X20 ="Critical", 'Patient Health Records'!W20 = "No"), "Ask for Readmission","No Action"))) -> No Action | V20: {=_xlfn.IFS(AND(T20="High Priority",'Patient Health Records'!W20="Yes",'Patient Health Records'!X20 = "Critical"),"Needs Attention", AND('Patient Health Records'!X20 <> "Critical", 'Patient Health Records'!W20 = "Yes"),"Monitor Later", AND('Patient Health Records'!X20 ="Critical", 'Patient Health Records'!W20 = "No"), "Ask for Readmission", TRUE, "No Action")} -> No Action
A21: PID0020 | B21: Krishna Patel | C21: Male | D21: 31-12-1968 | E21: =DATEVALUE(D21) -> 25203 | F21: =YEAR(E21) -> 1968 | G21: =$X$9-F21 -> 57 | H21: {=_xlfn.IFS( AND(G21>=21, G21<=30), "Young Adult", AND(G21>=31, G21<=45), "Adult", AND(G21>=46, G21<=60), "Middle-aged", AND(G21>=61, G21<=75), "Senior", AND(G21>=76, G21<=87), "Elderly", TRUE, "Out of Range" )} -> Middle-aged | I21: 15 | J21: Maharashtra | K21: West | L21: =VLOOKUP(J21,Facts!$A$2:$B$10,2,FALSE) -> West | M21: =HLOOKUP(J21,Facts!$D$13:$L$14,2,FALSE) -> West | N21: =_xlfn.XLOOKUP(L21,Facts!$B$2:$B$10,Facts!$A$2:$A$10,FALSE) -> Maharashtra | O21: =TRIM(B21) -> Krishna Patel | P21: {=_xlfn.TEXTSPLIT(O21," ")} -> Krishna | Q21: Patel | S21: =CONCATENATE(A21,"_",P21,".pdf") -> PID0020_Krishna.pdf | T21: =IF(AND(I21<5,'Billing Details'!F21>10000),"High Priority","Regular Followup") -> Regular Followup | U21: =IF(AND(T21="High Priority",'Patient Health Records'!W21="Yes",'Patient Health Records'!X21 = "Critical"),"Needs Attention",IF(AND('Patient Health Records'!X21 <> "Critical", 'Patient Health Records'!W21 = "Yes"),"Monitor Later",IF(AND('Patient Health Records'!X21 ="Critical", 'Patient Health Records'!W21 = "No"), "Ask for Readmission","No Action"))) -> No Action | V21: {=_xlfn.IFS(AND(T21="High Priority",'Patient Health Records'!W21="Yes",'Patient Health Records'!X21 = "Critical"),"Needs Attention", AND('Patient Health Records'!X21 <> "Critical", 'Patient Health Records'!W21 = "Yes"),"Monitor Later", AND('Patient Health Records'!X21 ="Critical", 'Patient Health Records'!W21 = "No"), "Ask for Readmission", TRUE, "No Action")} -> No Action
A22: PID0021 | B22: Aanya Reddy | C22: Female | D22: 31/12/1980 | E22: =DATEVALUE(D22) -> 29586 | F22: =YEAR(E22) -> 1980 | G22: =$X$9-F22 -> 45 | H22: {=_xlfn.IFS( AND(G22>=21, G22<=30), "Young Adult", AND(G22>=31, G22<=45), "Adult", AND(G22>=46, G22<=60), "Middle-aged", AND(G22>=61, G22<=75), "Senior", AND(G22>=76, G22<=87), "Elderly", TRUE, "Out of Range" )} -> Adult | I22: 30 | J22: Punjab | K22: North | L22: =VLOOKUP(J22,Facts!$A$2:$B$10,2,FALSE) -> North | M22: =HLOOKUP(J22,Facts!$D$13:$L$14,2,FALSE) -> North | N22: =_xlfn.XLOOKUP(L22,Facts!$B$2:$B$10,Facts!$A$2:$A$10,FALSE) -> Punjab | O22: =TRIM(B22) -> Aanya Reddy | P22: {=_xlfn.TEXTSPLIT(O22," ")} -> Aanya | Q22: Reddy | S22: =CONCATENATE(A22,"_",P22,".pdf") -> PID0021_Aanya.pdf | T22: =IF(AND(I22<5,'Billing Details'!F22>10000),"High Priority","Regular Followup") -> Regular Followup | U22: =IF(AND(T22="High Priority",'Patient Health Records'!W22="Yes",'Patient Health Records'!X22 = "Critical"),"Needs Attention",IF(AND('Patient Health Records'!X22 <> "Critical", 'Patient Health Records'!W22 = "Yes"),"Monitor Later",IF(AND('Patient Health Records'!X22 ="Critical", 'Patient Health Records'!W22 = "No"), "Ask for Readmission","No Action"))) -> No Action | V22: {=_xlfn.IFS(AND(T22="High Priority",'Patient Health Records'!W22="Yes",'Patient Health Records'!X22 = "Critical"),"Needs Attention", AND('Patient Health Records'!X22 <> "Critical", 'Patient Health Records'!W22 = "Yes"),"Monitor Later", AND('Patient Health Records'!X22 ="Critical", 'Patient Health Records'!W22 = "No"), "Ask for Readmission", TRUE, "No Action")} -> No Action
A23: PID0022 | B23: Diya Reddy | C23: Female | D23: 31/12/1978 | E23: =DATEVALUE(D23) -> 28855 | F23: =YEAR(E23) -> 1978 | G23: =$X$9-F23 -> 47 | H23: {=_xlfn.IFS( AND(G23>=21, G23<=30), "Young Adult", AND(G23>=31, G23<=45), "Adult", AND(G23>=46, G23<=60), "Middle-aged", AND(G23>=61, G23<=75), "Senior", AND(G23>=76, G23<=87), "Elderly", TRUE, "Out of Range" )} -> Middle-aged | I23: 2 | J23: Karnataka | K23: South | L23: =VLOOKUP(J23,Facts!$A$2:$B$10,2,FALSE) -> South | M23: =HLOOKUP(J23,Facts!$D$13:$L$14,2,FALSE) -> South | N23: =_xlfn.XLOOKUP(L23,Facts!$B$2:$B$10,Facts!$A$2:$A$10,FALSE) -> Tamil Nadu | O23: =TRIM(B23) -> Diya Reddy | P23: {=_xlfn.TEXTSPLIT(O23," ")} -> Diya | Q23: Reddy | S23: =CONCATENATE(A23,"_",P23,".pdf") -> PID0022_Diya.pdf | T23: =IF(AND(I23<5,'Billing Details'!F23>10000),"High Priority","Regular Followup") -> High Priority | U23: =IF(AND(T23="High Priority",'Patient Health Records'!W23="Yes",'Patient Health Records'!X23 = "Critical"),"Needs Attention",IF(AND('Patient Health Records'!X23 <> "Critical", 'Patient Health Records'!W23 = "Yes"),"Monitor Later",IF(AND('Patient Health Records'!X23 ="Critical", 'Patient Health Records'!W23 = "No"), "Ask for Readmission","No Action"))) -> Monitor Later | V23: {=_xlfn.IFS(AND(T23="High Priority",'Patient Health Records'!W23="Yes",'Patient Health Records'!X23 = "Critical"),"Needs Attention", AND('Patient Health Records'!X23 <> "Critical", 'Patient Health Records'!W23 = "Yes"),"Monitor Later", AND('Patient Health Records'!X23 ="Critical", 'Patient Health Records'!W23 = "No"), "Ask for Readmission", TRUE, "No Action")} -> Monitor Later
A24: PID0023 | B24: Vivaan Dev Sharma | C24: Male | D24: 31/12/1968 | E24: =DATEVALUE(D24) -> 25203 | F24: =YEAR(E24) -> 1968 | G24: =$X$9-F24 -> 57 | H24: {=_xlfn.IFS( AND(G24>=21, G24<=30), "Young Adult", AND(G24>=31, G24<=45), "Adult", AND(G24>=46, G24<=60), "Middle-aged", AND(G24>=61, G24<=75), "Senior", AND(G24>=76, G24<=87), "Elderly", TRUE, "Out of Range" )} -> Middle-aged | I24: 40 | J24: Karnataka | K24: South | L24: =VLOOKUP(J24,Facts!$A$2:$B$10,2,FALSE) -> South | M24: =HLOOKUP(J24,Facts!$D$13:$L$14,2,FALSE) -> South | N24: =_xlfn.XLOOKUP(L24,Facts!$B$2:$B$10,Facts!$A$2:$A$10,FALSE) -> Tamil Nadu | O24: =TRIM(B24) -> Vivaan Dev Sharma | P24: {=_xlfn.TEXTSPLIT(O24," ")} -> Vivaan | Q24: Dev | R24: Sharma | S24: =CONCATENATE(A24,"_",P24,".pdf") -> PID0023_Vivaan.pdf | T24: =IF(AND(I24<5,'Billing Details'!F24>10000),"High Priority","Regular Followup") -> Regular Followup | U24: =IF(AND(T24="High Priority",'Patient Health Records'!W24="Yes",'Patient Health Records'!X24 = "Critical"),"Needs Attention",IF(AND('Patient Health Records'!X24 <> "Critical", 'Patient Health Records'!W24 = "Yes"),"Monitor Later",IF(AND('Patient Health Records'!X24 ="Critical", 'Patient Health Records'!W24 = "No"), "Ask for Readmission","No Action"))) -> No Action | V24: {=_xlfn.IFS(AND(T24="High Priority",'Patient Health Records'!W24="Yes",'Patient Health Records'!X24 = "Critical"),"Needs Attention", AND('Patient Health Records'!X24 <> "Critical", 'Patient Health Records'!W24 = "Yes"),"Monitor Later", AND('Patient Health Records'!X24 ="Critical", 'Patient Health Records'!W24 = "No"), "Ask for Readmission", TRUE, "No Action")} -> No Action
A25: PID0024 | B25: Aarav Mehta | C25: Male | D25: 01/01/1964 | E25: =DATEVALUE(D25) -> 23377 | F25: =YEAR(E25) -> 1964 | G25: =$X$9-F25 -> 61 | H25: {=_xlfn.IFS( AND(G25>=21, G25<=30), "Young Adult", AND(G25>=31, G25<=45), "Adult", AND(G25>=46, G25<=60), "Middle-aged", AND(G25>=61, G25<=75), "Senior", AND(G25>=76, G25<=87), "Elderly", TRUE, "Out of Range" )} -> Senior | I25: 15 | J25: Maharashtra | K25: North | L25: =VLOOKUP(J25,Facts!$A$2:$B$10,2,FALSE) -> West | M25: =HLOOKUP(J25,Facts!$D$13:$L$14,2,FALSE) -> West | N25: =_xlfn.XLOOKUP(L25,Facts!$B$2:$B$10,Facts!$A$2:$A$10,FALSE) -> Maharashtra | O25: =TRIM(B25) -> Aarav Mehta | P25: {=_xlfn.TEXTSPLIT(O25," ")} -> Aarav | Q25: Mehta | S25: =CONCATENATE(A25,"_",P25,".pdf") -> PID0024_Aarav.pdf | T25: =IF(AND(I25<5,'Billing Details'!F25>10000),"High Priority","Regular Followup") -> Regular Followup | U25: =IF(AND(T25="High Priority",'Patient Health Records'!W25="Yes",'Patient Health Records'!X25 = "Critical"),"Needs Attention",IF(AND('Patient Health Records'!X25 <> "Critical", 'Patient Health Records'!W25 = "Yes"),"Monitor Later",IF(AND('Patient Health Records'!X25 ="Critical", 'Patient Health Records'!W25 = "No"), "Ask for Readmission","No Action"))) -> No Action | V25: {=_xlfn.IFS(AND(T25="High Priority",'Patient Health Records'!W25="Yes",'Patient Health Records'!X25 = "Critical"),"Needs Attention", AND('Patient Health Records'!X25 <> "Critical", 'Patient Health Records'!W25 = "Yes"),"Monitor Later", AND('Patient Health Records'!X25 ="Critical", 'Patient Health Records'!W25 = "No"), "Ask for Readmission", TRUE, "No Action")} -> No Action
A26: PID0025 | B26: Vivaan Kumar Patel | C26: Male | D26: 31/12/1988 | E26: =DATEVALUE(D26) -> 32508 | F26: =YEAR(E26) -> 1988 | G26: =$X$9-F26 -> 37 | H26: {=_xlfn.IFS( AND(G26>=21, G26<=30), "Young Adult", AND(G26>=31, G26<=45), "Adult", AND(G26>=46, G26<=60), "Middle-aged", AND(G26>=61, G26<=75), "Senior", AND(G26>=76, G26<=87), "Elderly", TRUE, "Out of Range" )} -> Adult | I26: 12 | J26: Maharashtra | K26: North | L26: =VLOOKUP(J26,Facts!$A$2:$B$10,2,FALSE) -> West | M26: =HLOOKUP(J26,Facts!$D$13:$L$14,2,FALSE) -> West | N26: =_xlfn.XLOOKUP(L26,Facts!$B$2:$B$10,Facts!$A$2:$A$10,FALSE) -> Maharashtra | O26: =TRIM(B26) -> Vivaan Kumar Patel | P26: {=_xlfn.TEXTSPLIT(O26," ")} -> Vivaan | Q26: Kumar | R26: Patel | S26: =CONCATENATE(A26,"_",P26,".pdf") -> PID0025_Vivaan.pdf | T26: =IF(AND(I26<5,'Billing Details'!F26>10000),"High Priority","Regular Followup") -> Regular Followup | U26: =IF(AND(T26="High Priority",'Patient Health Records'!W26="Yes",'Patient Health Records'!X26 = "Critical"),"Needs Attention",IF(AND('Patient Health Records'!X26 <> "Critical", 'Patient Health Records'!W26 = "Yes"),"Monitor Later",IF(AND('Patient Health Records'!X26 ="Critical", 'Patient Health Records'!W26 = "No"), "Ask for Readmission","No Action"))) -> Monitor Later | V26: {=_xlfn.IFS(AND(T26="High Priority",'Patient Health Records'!W26="Yes",'Patient Health Records'!X26 = "Critical"),"Needs Attention", AND('Patient Health Records'!X26 <> "Critical", 'Patient Health Records'!W26 = "Yes"),"Monitor Later", AND('Patient Health Records'!X26 ="Critical", 'Patient Health Records'!W26 = "No"), "Ask for Readmission", TRUE, "No Action")} -> Monitor Later
A27: PID0026 | B27: Aanya Priya Reddy | C27: Female | D27: 31/12/1968 | E27: =DATEVALUE(D27) -> 25203 | F27: =YEAR(E27) -> 1968 | G27: =$X$9-F27 -> 57 | H27: {=_xlfn.IFS( AND(G27>=21, G27<=30), "Young Adult", AND(G27>=31, G27<=45), "Adult", AND(G27>=46, G27<=60), "Middle-aged", AND(G27>=61, G27<=75), "Senior", AND(G27>=76, G27<=87), "Elderly", TRUE, "Out of Range" )} -> Middle-aged | I27: 2 | J27: Uttar Pradesh | K27: North | L27: =VLOOKUP(J27,Facts!$A$2:$B$10,2,FALSE) -> North | M27: =HLOOKUP(J27,Facts!$D$13:$L$14,2,FALSE) -> North | N27: =_xlfn.XLOOKUP(L27,Facts!$B$2:$B$10,Facts!$A$2:$A$10,FALSE) -> Punjab | O27: =TRIM(B27) -> Aanya Priya Reddy | P27: {=_xlfn.TEXTSPLIT(O27," ")} -> Aanya | Q27: Priya | R27: Reddy | S27: =CONCATENATE(A27,"_",P27,".pdf") -> PID0026_Aanya.pdf | T27: =IF(AND(I27<5,'Billing Details'!F27>10000),"High Priority","Regular Followup") -> High Priority | U27: =IF(AND(T27="High Priority",'Patient Health Records'!W27="Yes",'Patient Health Records'!X27 = "Critical"),"Needs Attention",IF(AND('Patient Health Records'!X27 <> "Critical", 'Patient Health Records'!W27 = "Yes"),"Monitor Later",IF(AND('Patient Health Records'!X27 ="Critical", 'Patient Health Records'!W27 = "No"), "Ask for Readmission","No Action"))) -> No Action | V27: {=_xlfn.IFS(AND(T27="High Priority",'Patient Health Records'!W27="Yes",'Patient Health Records'!X27 = "Critical"),"Needs Attention", AND('Patient Health Records'!X27 <> "Critical", 'Patient Health Records'!W27 = "Yes"),"Monitor Later", AND('Patient Health Records'!X27 ="Critical", 'Patient Health Records'!W27 = "No"), "Ask for Readmission", TRUE, "No Action")} -> No Action
A28: PID0027 | B28: Riya Mehta | C28: Female | D28: 31-12-1978 | E28: =DATEVALUE(D28) -> 28855 | F28: =YEAR(E28) -> 1978 | G28: =$X$9-F28 -> 47 | H28: {=_xlfn.IFS( AND(G28>=21, G28<=30), "Young Adult", AND(G28>=31, G28<=45), "Adult", AND(G28>=46, G28<=60), "Middle-aged", AND(G28>=61, G28<=75), "Senior", AND(G28>=76, G28<=87), "Elderly", TRUE, "Out of Range" )} -> Middle-aged | J28: Gujarat | K28: East | L28: =VLOOKUP(J28,Facts!$A$2:$B$10,2,FALSE) -> West | M28: =HLOOKUP(J28,Facts!$D$13:$L$14,2,FALSE) -> West | N28: =_xlfn.XLOOKUP(L28,Facts!$B$2:$B$10,Facts!$A$2:$A$10,FALSE) -> Maharashtra | O28: =TRIM(B28) -> Riya Mehta | P28: {=_xlfn.TEXTSPLIT(O28," ")} -> Riya | Q28: Mehta | S28: =CONCATENATE(A28,"_",P28,".pdf") -> PID0027_Riya.pdf | T28: =IF(AND(I28<5,'Billing Details'!F28>10000),"High Priority","Regular Followup") -> High Priority | U28: =IF(AND(T28="High Priority",'Patient Health Records'!W28="Yes",'Patient Health Records'!X28 = "Critical"),"Needs Attention",IF(AND('Patient Health Records'!X28 <> "Critical", 'Patient Health Records'!W28 = "Yes"),"Monitor Later",IF(AND('Patient Health Records'!X28 ="Critical", 'Patient Health Records'!W28 = "No"), "Ask for Readmission","No Action"))) -> Needs Attention | V28: {=_xlfn.IFS(AND(T28="High Priority",'Patient Health Records'!W28="Yes",'Patient Health Records'!X28 = "Critical"),"Needs Attention", AND('Patient Health Records'!X28 <> "Critical", 'Patient Health Records'!W28 = "Yes"),"Monitor Later", AND('Patient Health Records'!X28 ="Critical", 'Patient Health Records'!W28 = "No"), "Ask for Readmission", TRUE, "No Action")} -> Needs Attention
A29: PID0028 | B29: Aarav Sharma | C29: Male | D29: 31/12/1993 | E29: =DATEVALUE(D29) -> 34334 | F29: =YEAR(E29) -> 1993 | G29: =$X$9-F29 -> 32 | H29: {=_xlfn.IFS( AND(G29>=21, G29<=30), "Young Adult", AND(G29>=31, G29<=45), "Adult", AND(G29>=46, G29<=60), "Middle-aged", AND(G29>=61, G29<=75), "Senior", AND(G29>=76, G29<=87), "Elderly", TRUE, "Out of Range" )} -> Adult | I29: 25 | J29: Karnataka | K29: West | L29: =VLOOKUP(J29,Facts!$A$2:$B$10,2,FALSE) -> South | M29: =HLOOKUP(J29,Facts!$D$13:$L$14,2,FALSE) -> South | N29: =_xlfn.XLOOKUP(L29,Facts!$B$2:$B$10,Facts!$A$2:$A$10,FALSE) -> Tamil Nadu | O29: =TRIM(B29) -> Aarav Sharma | P29: {=_xlfn.TEXTSPLIT(O29," ")} -> Aarav | Q29: Sharma | S29: =CONCATENATE(A29,"_",P29,".pdf") -> PID0028_Aarav.pdf | T29: =IF(AND(I29<5,'Billing Details'!F29>10000),"High Priority","Regular Followup") -> Regular Followup | U29: =IF(AND(T29="High Priority",'Patient Health Records'!W29="Yes",'Patient Health Records'!X29 = "Critical"),"Needs Attention",IF(AND('Patient Health Records'!X29 <> "Critical", 'Patient Health Records'!W29 = "Yes"),"Monitor Later",IF(AND('Patient Health Records'!X29 ="Critical", 'Patient Health Records'!W29 = "No"), "Ask for Readmission","No Action"))) -> Monitor Later | V29: {=_xlfn.IFS(AND(T29="High Priority",'Patient Health Records'!W29="Yes",'Patient Health Records'!X29 = "Critical"),"Needs Attention", AND('Patient Health Records'!X29 <> "Critical", 'Patient Health Records'!W29 = "Yes"),"Monitor Later", AND('Patient Health Records'!X29 ="Critical", 'Patient Health Records'!W29 = "No"), "Ask for Readmission", TRUE, "No Action")} -> Monitor Later
A30: PID0029 | B30: Krishna Sharma | C30: Male | D30: 31/12/1988 | E30: =DATEVALUE(D30) -> 32508 | F30: =YEAR(E30) -> 1988 | G30: =$X$9-F30 -> 37 | H30: {=_xlfn.IFS( AND(G30>=21, G30<=30), "Young Adult", AND(G30>=31, G30<=45), "Adult", AND(G30>=46, G30<=60), "Middle-aged", AND(G30>=61, G30<=75), "Senior", AND(G30>=76, G30<=87), "Elderly", TRUE, "Out of Range" )} -> Adult | I30: 2 | J30: Uttar Pradesh | K30: West | L30: =VLOOKUP(J30,Facts!$A$2:$B$10,2,FALSE) -> North | M30: =HLOOKUP(J30,Facts!$D$13:$L$14,2,FALSE) -> North | N30: =_xlfn.XLOOKUP(L30,Facts!$B$2:$B$10,Facts!$A$2:$A$10,FALSE) -> Punjab | O30: =TRIM(B30) -> Krishna Sharma | P30: {=_xlfn.TEXTSPLIT(O30," ")} -> Krishna | Q30: Sharma | S30: =CONCATENATE(A30,"_",P30,".pdf") -> PID0029_Krishna.pdf | T30: =IF(AND(I30<5,'Billing Details'!F30>10000),"High Priority","Regular Followup") -> High Priority | U30: =IF(AND(T30="High Priority",'Patient Health Records'!W30="Yes",'Patient Health Records'!X30 = "Critical"),"Needs Attention",IF(AND('Patient Health Records'!X30 <> "Critical", 'Patient Health Records'!W30 = "Yes"),"Monitor Later",IF(AND('Patient Health Records'!X30 ="Critical", 'Patient Health Records'!W30 = "No"), "Ask for Readmission","No Action"))) -> Monitor Later | V30: {=_xlfn.IFS(AND(T30="High Priority",'Patient Health Records'!W30="Yes",'Patient Health Records'!X30 = "Critical"),"Needs Attention", AND('Patient Health Records'!X30 <> "Critical", 'Patient Health Records'!W30 = "Yes"),"Monitor Later", AND('Patient Health Records'!X30 ="Critical", 'Patient Health Records'!W30 = "No"), "Ask for Readmission", TRUE, "No Action")} -> Monitor Later
A31: PID0030 | B31: Aanya Priya Reddy | C31: Female | D31: 31/12/1998 | E31: =DATEVALUE(D31) -> 36160 | F31: =YEAR(E31) -> 1998 | G31: =$X$9-F31 -> 27 | H31: {=_xlfn.IFS( AND(G31>=21, G31<=30), "Young Adult", AND(G31>=31, G31<=45), "Adult", AND(G31>=46, G31<=60), "Middle-aged", AND(G31>=61, G31<=75), "Senior", AND(G31>=76, G31<=87), "Elderly", TRUE, "Out of Range" )} -> Young Adult | I31: 30 | J31: Uttar Pradesh | K31: East | L31: =VLOOKUP(J31,Facts!$A$2:$B$10,2,FALSE) -> North | M31: =HLOOKUP(J31,Facts!$D$13:$L$14,2,FALSE) -> North | N31: =_xlfn.XLOOKUP(L31,Facts!$B$2:$B$10,Facts!$A$2:$A$10,FALSE) -> Punjab | O31: =TRIM(B31) -> Aanya Priya Reddy | P31: {=_xlfn.TEXTSPLIT(O31," ")} -> Aanya | Q31: Priya | R31: Reddy | S31: =CONCATENATE(A31,"_",P31,".pdf") -> PID0030_Aanya.pdf | T31: =IF(AND(I31<5,'Billing Details'!F31>10000),"High Priority","Regular Followup") -> Regular Followup | U31: =IF(AND(T31="High Priority",'Patient Health Records'!W31="Yes",'Patient Health Records'!X31 = "Critical"),"Needs Attention",IF(AND('Patient Health Records'!X31 <> "Critical", 'Patient Health Records'!W31 = "Yes"),"Monitor Later",IF(AND('Patient Health Records'!X31 ="Critical", 'Patient Health Records'!W31 = "No"), "Ask for Readmission","No Action"))) -> No Action | V31: {=_xlfn.IFS(AND(T31="High Priority",'Patient Health Records'!W31="Yes",'Patient Health Records'!X31 = "Critical"),"Needs Attention", AND('Patient Health Records'!X31 <> "Critical", 'Patient Health Records'!W31 = "Yes"),"Monitor Later", AND('Patient Health Records'!X31 ="Critical", 'Patient Health Records'!W31 = "No"), "Ask for Readmission", TRUE, "No Action")} -> No Action
A32: PID0031 | B32: Shreya Sharma | C32: Female | D32: 31/12/1981 | E32: =DATEVALUE(D32) -> 29951 | F32: =YEAR(E32) -> 1981 | G32: =$X$9-F32 -> 44 | H32: {=_xlfn.IFS( AND(G32>=21, G32<=30), "Young Adult", AND(G32>=31, G32<=45), "Adult", AND(G32>=46, G32<=60), "Middle-aged", AND(G32>=61, G32<=75), "Senior", AND(G32>=76, G32<=87), "Elderly", TRUE, "Out of Range" )} -> Adult | I32: 1 | J32: Uttar Pradesh | K32: North | L32: =VLOOKUP(J32,Facts!$A$2:$B$10,2,FALSE) -> North | M32: =HLOOKUP(J32,Facts!$D$13:$L$14,2,FALSE) -> North | N32: =_xlfn.XLOOKUP(L32,Facts!$B$2:$B$10,Facts!$A$2:$A$10,FALSE) -> Punjab | O32: =TRIM(B32) -> Shreya Sharma | P32: {=_xlfn.TEXTSPLIT(O32," ")} -> Shreya | Q32: Sharma | S32: =CONCATENATE(A32,"_",P32,".pdf") -> PID0031_Shreya.pdf | T32: =IF(AND(I32<5,'Billing Details'!F32>10000),"High Priority","Regular Followup") -> High Priority | U32: =IF(AND(T32="High Priority",'Patient Health Records'!W32="Yes",'Patient Health Records'!X32 = "Critical"),"Needs Attention",IF(AND('Patient Health Records'!X32 <> "Critical", 'Patient Health Records'!W32 = "Yes"),"Monitor Later",IF(AND('Patient Health Records'!X32 ="Critical", 'Patient Health Records'!W32 = "No"), "Ask for Readmission","No Action"))) -> Ask for Readmission | V32: {=_xlfn.IFS(AND(T32="High Priority",'Patient Health Records'!W32="Yes",'Patient Health Records'!X32 = "Critical"),"Needs Attention", AND('Patient Health Records'!X32 <> "Critical", 'Patient Health Records'!W32 = "Yes"),"Monitor Later", AND('Patient Health Records'!X32 ="Critical", 'Patient Health Records'!W32 = "No"), "Ask for Readmission", TRUE, "No Action")} -> Ask for Readmission
A33: PID0032 | B33: Isha Gupta | C33: Female | D33: 31/12/1973 | E33: =DATEVALUE(D33) -> 27029 | F33: =YEAR(E33) -> 1973 | G33: =$X$9-F33 -> 52 | H33: {=_xlfn.IFS( AND(G33>=21, G33<=30), "Young Adult", AND(G33>=31, G33<=45), "Adult", AND(G33>=46, G33<=60), "Middle-aged", AND(G33>=61, G33<=75), "Senior", AND(G33>=76, G33<=87), "Elderly", TRUE, "Out of Range" )} -> Middle-aged | I33: 9 | J33: Tamil Nadu | K33: South | L33: =VLOOKUP(J33,Facts!$A$2:$B$10,2,FALSE) -> South | M33: =HLOOKUP(J33,Facts!$D$13:$L$14,2,FALSE) -> South | N33: =_xlfn.XLOOKUP(L33,Facts!$B$2:$B$10,Facts!$A$2:$A$10,FALSE) -> Tamil Nadu | O33: =TRIM(B33) -> Isha Gupta | P33: {=_xlfn.TEXTSPLIT(O33," ")} -> Isha | Q33: Gupta | S33: =CONCATENATE(A33,"_",P33,".pdf") -> PID0032_Isha.pdf | T33: =IF(AND(I33<5,'Billing Details'!F33>10000),"High Priority","Regular Followup") -> Regular Followup | U33: =IF(AND(T33="High Priority",'Patient Health Records'!W33="Yes",'Patient Health Records'!X33 = "Critical"),"Needs Attention",IF(AND('Patient Health Records'!X33 <> "Critical", 'Patient Health Records'!W33 = "Yes"),"Monitor Later",IF(AND('Patient Health Records'!X33 ="Critical", 'Patient Health Records'!W33 = "No"), "Ask for Readmission","No Action"))) -> No Action | V33: {=_xlfn.IFS(AND(T33="High Priority",'Patient Health Records'!W33="Yes",'Patient Health Records'!X33 = "Critical"),"Needs Attention", AND('Patient Health Records'!X33 <> "Critical", 'Patient Health Records'!W33 = "Yes"),"Monitor Later", AND('Patient Health Records'!X33 ="Critical", 'Patient Health Records'!W33 = "No"), "Ask for Readmission", TRUE, "No Action")} -> No Action
A34: PID0033 | B34: Diya Sharma | C34: Female | D34: 31/12/1998 | E34: =DATEVALUE(D34) -> 36160 | F34: =YEAR(E34) -> 1998 | G34: =$X$9-F34 -> 27 | H34: {=_xlfn.IFS( AND(G34>=21, G34<=30), "Young Adult", AND(G34>=31, G34<=45), "Adult", AND(G34>=46, G34<=60), "Middle-aged", AND(G34>=61, G34<=75), "Senior", AND(G34>=76, G34<=87), "Elderly", TRUE, "Out of Range" )} -> Young Adult | I34: 15 | J34: Maharashtra | K34: West | L34: =VLOOKUP(J34,Facts!$A$2:$B$10,2,FALSE) -> West | M34: =HLOOKUP(J34,Facts!$D$13:$L$14,2,FALSE) -> West | N34: =_xlfn.XLOOKUP(L34,Facts!$B$2:$B$10,Facts!$A$2:$A$10,FALSE) -> Maharashtra | O34: =TRIM(B34) -> Diya Sharma | P34: {=_xlfn.TEXTSPLIT(O34," ")} -> Diya | Q34: Sharma | S34: =CONCATENATE(A34,"_",P34,".pdf") -> PID0033_Diya.pdf | T34: =IF(AND(I34<5,'Billing Details'!F34>10000),"High Priority","Regular Followup") -> Regular Followup | U34: =IF(AND(T34="High Priority",'Patient Health Records'!W34="Yes",'Patient Health Records'!X34 = "Critical"),"Needs Attention",IF(AND('Patient Health Records'!X34 <> "Critical", 'Patient Health Records'!W34 = "Yes"),"Monitor Later",IF(AND('Patient Health Records'!X34 ="Critical", 'Patient Health Records'!W34 = "No"), "Ask for Readmission","No Action"))) -> Monitor Later | V34: {=_xlfn.IFS(AND(T34="High Priority",'Patient Health Records'!W34="Yes",'Patient Health Records'!X34 = "Critical"),"Needs Attention", AND('Patient Health Records'!X34 <> "Critical", 'Patient Health Records'!W34 = "Yes"),"Monitor Later", AND('Patient Health Records'!X34 ="Critical", 'Patient Health Records'!W34 = "No"), "Ask for Readmission", TRUE, "No Action")} -> Monitor Later
A35: PID0034 | B35: Aditya Mehta | C35: Male | D35: 01/01/1984 | E35: =DATEVALUE(D35) -> 30682 | F35: =YEAR(E35) -> 1984 | G35: =$X$9-F35 -> 41 | H35: {=_xlfn.IFS( AND(G35>=21, G35<=30), "Young Adult", AND(G35>=31, G35<=45), "Adult", AND(G35>=46, G35<=60), "Middle-aged", AND(G35>=61, G35<=75), "Senior", AND(G35>=76, G35<=87), "Elderly", TRUE, "Out of Range" )} -> Adult | I35: 15 | J35: Punjab | K35: South | L35: =VLOOKUP(J35,Facts!$A$2:$B$10,2,FALSE) -> North | M35: =HLOOKUP(J35,Facts!$D$13:$L$14,2,FALSE) -> North | N35: =_xlfn.XLOOKUP(L35,Facts!$B$2:$B$10,Facts!$A$2:$A$10,FALSE) -> Punjab | O35: =TRIM(B35) -> Aditya Mehta | P35: {=_xlfn.TEXTSPLIT(O35," ")} -> Aditya | Q35: Mehta | S35: =CONCATENATE(A35,"_",P35,".pdf") -> PID0034_Aditya.pdf | T35: =IF(AND(I35<5,'Billing Details'!F35>10000),"High Priority","Regular Followup") -> Regular Followup | U35: =IF(AND(T35="High Priority",'Patient Health Records'!W35="Yes",'Patient Health Records'!X35 = "Critical"),"Needs Attention",IF(AND('Patient Health Records'!X35 <> "Critical", 'Patient Health Records'!W35 = "Yes"),"Monitor Later",IF(AND('Patient Health Records'!X35 ="Critical", 'Patient Health Records'!W35 = "No"), "Ask for Readmission","No Action"))) -> No Action | V35: {=_xlfn.IFS(AND(T35="High Priority",'Patient Health Records'!W35="Yes",'Patient Health Records'!X35 = "Critical"),"Needs Attention", AND('Patient Health Records'!X35 <> "Critical", 'Patient Health Records'!W35 = "Yes"),"Monitor Later", AND('Patient Health Records'!X35 ="Critical", 'Patient Health Records'!W35 = "No"), "Ask for Readmission", TRUE, "No Action")} -> No Action
A36: PID0035 | B36: Krishna Sharma | C36: Male | D36: 01/01/1976 | E36: =DATEVALUE(D36) -> 27760 | F36: =YEAR(E36) -> 1976 | G36: =$X$9-F36 -> 49 | H36: {=_xlfn.IFS( AND(G36>=21, G36<=30), "Young Adult", AND(G36>=31, G36<=45), "Adult", AND(G36>=46, G36<=60), "Middle-aged", AND(G36>=61, G36<=75), "Senior", AND(G36>=76, G36<=87), "Elderly", TRUE, "Out of Range" )} -> Middle-aged | I36: 2 | J36: Uttar Pradesh | K36: East | L36: =VLOOKUP(J36,Facts!$A$2:$B$10,2,FALSE) -> North | M36: =HLOOKUP(J36,Facts!$D$13:$L$14,2,FALSE) -> North | N36: =_xlfn.XLOOKUP(L36,Facts!$B$2:$B$10,Facts!$A$2:$A$10,FALSE) -> Punjab | O36: =TRIM(B36) -> Krishna Sharma | P36: {=_xlfn.TEXTSPLIT(O36," ")} -> Krishna | Q36: Sharma | S36: =CONCATENATE(A36,"_",P36,".pdf") -> PID0035_Krishna.pdf | T36: =IF(AND(I36<5,'Billing Details'!F36>10000),"High Priority","Regular Followup") -> High Priority | U36: =IF(AND(T36="High Priority",'Patient Health Records'!W36="Yes",'Patient Health Records'!X36 = "Critical"),"Needs Attention",IF(AND('Patient Health Records'!X36 <> "Critical", 'Patient Health Records'!W36 = "Yes"),"Monitor Later",IF(AND('Patient Health Records'!X36 ="Critical", 'Patient Health Records'!W36 = "No"), "Ask for Readmission","No Action"))) -> Needs Attention | V36: {=_xlfn.IFS(AND(T36="High Priority",'Patient Health Records'!W36="Yes",'Patient Health Records'!X36 = "Critical"),"Needs Attention", AND('Patient Health Records'!X36 <> "Critical", 'Patient Health Records'!W36 = "Yes"),"Monitor Later", AND('Patient Health Records'!X36 ="Critical", 'Patient Health Records'!W36 = "No"), "Ask for Readmission", TRUE, "No Action")} -> Needs Attention
A37: PID0036 | B37: Riya Gupta | C37: Female | D37: 31/12/1968 | E37: =DATEVALUE(D37) -> 25203 | F37: =YEAR(E37) -> 1968 | G37: =$X$9-F37 -> 57 | H37: {=_xlfn.IFS( AND(G37>=21, G37<=30), "Young Adult", AND(G37>=31, G37<=45), "Adult", AND(G37>=46, G37<=60), "Middle-aged", AND(G37>=61, G37<=75), "Senior", AND(G37>=76, G37<=87), "Elderly", TRUE, "Out of Range" )} -> Middle-aged | I37: 4 | J37: Punjab | K37: North | L37: =VLOOKUP(J37,Facts!$A$2:$B$10,2,FALSE) -> North | M37: =HLOOKUP(J37,Facts!$D$13:$L$14,2,FALSE) -> North | N37: =_xlfn.XLOOKUP(L37,Facts!$B$2:$B$10,Facts!$A$2:$A$10,FALSE) -> Punjab | O37: =TRIM(B37) -> Riya Gupta | P37: {=_xlfn.TEXTSPLIT(O37," ")} -> Riya | Q37: Gupta | S37: =CONCATENATE(A37,"_",P37,".pdf") -> PID0036_Riya.pdf | T37: =IF(AND(I37<5,'Billing Details'!F37>10000),"High Priority","Regular Followup") -> High Priority | U37: =IF(AND(T37="High Priority",'Patient Health Records'!W37="Yes",'Patient Health Records'!X37 = "Critical"),"Needs Attention",IF(AND('Patient Health Records'!X37 <> "Critical", 'Patient Health Records'!W37 = "Yes"),"Monitor Later",IF(AND('Patient Health Records'!X37 ="Critical", 'Patient Health Records'!W37 = "No"), "Ask for Readmission","No Action"))) -> No Action | V37: {=_xlfn.IFS(AND(T37="High Priority",'Patient Health Records'!W37="Yes",'Patient Health Records'!X37 = "Critical"),"Needs Attention", AND('Patient Health Records'!X37 <> "Critical", 'Patient Health Records'!W37 = "Yes"),"Monitor Later", AND('Patient Health Records'!X37 ="Critical", 'Patient Health Records'!W37 = "No"), "Ask for Readmission", TRUE, "No Action")} -> No Action
